Workbook
Name analysis_date: recency!$A$7
Name frequency_threshold: frequency!$A$7
Name recency_threshold: recency!$A$13
Name return_window: recency!$A$10
Name Slicer_Region: #N/A

Sheet RFM Analysis
A1: User CMA Smart & Secure : Applied Data Analytics Training Center.
A2: http://www.facebook.com/cma.01012020
A3: Email: info@usercma.com Phone: 09 44717 2115
B5: 📊 | C5: The Gold Standard: RFM Analysis (Segmentation, Descriptive Analytics)
B8: 💡 | C8: What is RFM Analysis?
C9: RFM Analysis is a customer segmentation technique based on purchasing behavior using three factors:
C10: R — Recency: How recently a customer purchased (Engagement)
C11: F — Frequency: How often they purchase (Loyalty)
C12: M — Monetary: How much money they spend (Value)
B14: 💡 | C14: Why Should You Use RFM Analysis?
C15: Identify high-value customers
C16: Detect loyal vs inactive customers
C17: Improve marketing targeting
C18: Increase customer retention
C19: Support data-driven business decisions
B23: 💡 | C23: How to Use RFM Analysis — Step-by-Step
B25: 1️⃣ | C25: Define Business Objective
C26: Examples: Improve customer retention, Target high-value segments, Reduce churn.
B28: 2️⃣ | C28: Prepare Data
C29: Required fields (at least):
C30: Customer ID
C31: Transaction Date
C32: Invoice / Order ID
C33: Transaction Amount
B35: 3️⃣ | C35: Calculate RFM Metrics
C36: Recency: Days since last purchase (Recency = Analysis Date – Last Purchase Date)
C37: Frequency: Number of transactions count
C38: Monetary: Total or average spending
B40: 4️⃣ | C40: Score Customers | F40: Criteria | G40: (1) Quintiles (1–5 Scoring) | H40: (2) Median Split (High/Low) | I40: (3) Advanced (Return / Repeat / Pareto)
C41: Common approach: Rank into 1–5 score groups (quintiles) | F41: Concept | G41: Divide customers into 5 equal groups | H41: Split customers into 2 groups using median | I41: Use business-driven thresholds based on behavior patterns
C42: Simple approach: Rank into High-Low groups with Median splitting | F42: Complexity | G42: Medium | H42: Very Low | I42: High
C43: Advanced: Return-rate analysis for R, Repeat-rate analysis for F, and Pareto (80/20) Principle for M. | F43: Ease of Implementation (Excel) | G43: Easy | H43: Very Easy | I43: Moderate to Advanced
F44: Business Interpretability | G44: Medium | H44: High (very intuitive) | I44: Very High (directly linked to behavior)
B45: 5️⃣ | C45: Create Customer Segments | F45: Statistical Accuracy | G45: Medium (relative ranking only) | H45: Low (too simplified) | I45: High (behavior-based insights)
C46: Common approach: Combining R(1-5), F(1-5), M(1-5) (125 segments need to handle) (depend on business | F46: Sensitivity to Data Distribution | G46: High (can distort skewed data) | H46: Medium | I46: Low (based on actual patterns)
C47: capacity and actionability) | F47: Actionability | G47: Medium | H47: Low–Medium | I47: Very High
F48: Use of Business Logic | G48: ❌ No | H48: ❌ No | I48: ✅ Yes
C49: Simple approach : Combining R(H-L), F(H-L), M (H-L) (Only 8 segments need to handle) | F49: Handles Skewed Data (common in sales) | G49: ❌ Weak | H49: ❌ Weak | I49: ✅ Strong
F50: Segmentation Power | G50: Medium (5×5×5 combinations) | H50: Low (only 2×2×2) | I50: Very Strong (meaningful segmentation)
C51: Advanced: Combining R(H-L), F(H-L), M (H-L) (Only 8 segments need to handle) | F51: Real-world Usage | G51: Very Common (textbook & tools) | H51: Rare in serious analytics | I51: Used by advanced analysts & businesses
...

Sheet RFM_Table
A1: User CMA Smart & Secure : Applied Data Analytics Training Center.
A2: http://www.facebook.com/cma.01012020
A3: Email: info@usercma.com Phone: 09 44717 2115
A5: RFM Segmentation Table
A7: RFM Score | B7: Segment Name | C7: Customer Meaning | D7: Typical Risk Level | E7: Recommended Actions
A8: HHH | B8: 🥇 Champions | C8: Recently active, frequent, high spenders | D8: Very Low | E8: Loyalty rewards, VIP programs, referrals
A9: HHL | B9: 💎 Loyal High Value | C9: Active & loyal but moderate spending | D9: Low | E9: Upsell, cross-sell, premium offers
A10: HLH | B10: 🛒 Big Spenders (Occasional) | C10: Spend high but purchase less often | D10: Medium | E10: Engagement campaigns, personalized offers
A11: HLL | B11: 🌱 Potential Loyalists | C11: Recent customers with low history | D11: Medium | E11: Onboarding, nurture campaigns
A12: LHH | B12: ⚠️ At Risk High Value | C12: Previously valuable but inactive | D12: High | E12: Win-back campaigns, special incentives
A13: LHL | B13: 🔁 Former Loyal Low Spend | C13: Loyal before but lower value now | D13: Medium–High | E13: Re-engagement, bundle offers
A14: LLH | B14: 💸 Lost High Spenders | C14: High spenders but long inactive | D14: Very High | E14: Targeted reactivation, exclusive promotions
A15: LLL | B15: 💤 Lost / Low Value | C15: Low engagement, low spend | D15: Low–Medium (Low ROI) | E15: Minimal effort, mass campaigns only

Sheet raw_rfm
A1: User CMA Smart & Secure : Applied Data Analytics Training Center.
A2: http://www.facebook.com/cma.01012020
A3: Email: info@usercma.com Phone: 09 44717 2115
A5: raw_rfm_sales_transactions_(V2).csv
A6: https://www.kaggle.com/datasets/charmmyaeaung/raw-sales-dataset-for-rfm-customer-segmentation
A8: Transaction ID | B8: Date | C8: Product ID | D8: Product Name | E8: Product Category | F8: Quantity | G8: PPU | H8: Amount | I8: Customer ID | J8: Region
A9: T000001 | B9: 45658 | C9: PROD-006 | D9: A4 Printer Paper (500 Sheets) | E9: Office Supplies | F9: 13 | G9: 25000 | H9: 325000 | I9: Customer-190 | J9: Yangon
A10: T000002 | B10: 45658 | C10: PROD-006 | D10: A4 Printer Paper (500 Sheets) | E10: Office Supplies | F10: 500 | G10: 25000 | H10: 12500000 | I10: Customer-985 | J10: Bago
A11: T000003 | B11: 45658 | C11: PROD-009 | D11: Adjustable Monitor Arm | E11: Furniture | F11: 25 | G11: 180000 | H11: 4500000 | I11: Customer-625 | J11: Mandalay
A12: T000004 | B12: 45658 | C12: PROD-002 | D12: Wireless Mechanical Keyboard | E12: Electronics | F12: 41 | G12: 350000 | H12: 14350000 | I12: Customer-882 | J12: Yangon
A13: T000005 | B13: 45658 | C13: PROD-009 | D13: Adjustable Monitor Arm | E13: Furniture | F13: 28 | G13: 180000 | H13: 5040000 | I13: Customer-801 | J13: Bago
A14: T000006 | B14: 45658 | C14: PROD-007 | D14: USB-C Docking Station | E14: Electronics | F14: 7 | G14: 250000 | H14: 1750000 | I14: Customer-666 | J14: Yangon
A15: T000007 | B15: 45658 | C15: PROD-009 | D15: Adjustable Monitor Arm | E15: Furniture | F15: 35 | G15: 180000 | H15: 6300000 | I15: Customer-999 | J15: Naypyitaw
A16: T000008 | B16: 45658 | C16: PROD-008 | D16: Executive Ballpoint Pen Box | E16: Office Supplies | F16: 21 | G16: 120000 | H16: 2520000 | I16: Customer-364 | J16: Taunggyi
A17: T000009 | B17: 45658 | C17: PROD-007 | D17: USB-C Docking Station | E17: Electronics | F17: 32 | G17: 250000 | H17: 8000000 | I17: Customer-803 | J17: Taunggyi
A18: T000010 | B18: 45659 | C18: PROD-002 | D18: Wireless Mechanical Keyboard | E18: Electronics | F18: 21 | G18: 350000 | H18: 7350000 | I18: Customer-931 | J18: Yangon
A19: T000011 | B19: 45659 | C19: PROD-003 | D19: 27-inch 4K Monitor | E19: Electronics | F19: 30 | G19: 1200000 | H19: 36000000 | I19: Customer-469 | J19: Taunggyi
A20: T000012 | B20: 45659 | C20: PROD-004 | D20: Standing Desk Converter | E20: Furniture | F20: 12 | G20: 500000 | H20: 6000000 | I20: Customer-822 | J20: Naypyitaw
... A2008: T002000 | B2008: 46022 | C2008: PROD-007 | D2008: USB-C Docking Station | E2008: Electronics | F2008: 11 | G2008: 250000 | H2008: 2750000 | I2008: Customer-126 | J2008: Yangon

Sheet WK01
A1: User CMA Smart & Secure : Applied Data Analytics Training Center.
A2: http://www.facebook.com/cma.01012020
A3: Email: info@usercma.com Phone: 09 44717 2115
P4: recency | Q4: =MEDIAN(Q6:Q817) -> 94 | R4: =MEDIAN(R6:R817) -> 2 | S4: =MEDIAN($S$6:$S$817) -> 18350000 | T4: RFM (Median Splitting Option) | AG4: Advanced RFM (Return / Repeat / Pareto)
B5: Transaction ID | C5: Date | D5: Product ID | E5: Product Name | F5: Product Category | G5: Quantity | H5: PPU | I5: Amount | J5: Customer ID | K5: Region | N5: Customer ID | O5: Region | P5: Last Purchase Date | Q5: Day Gap | R5: Transaction Count | S5: Total Amount | T5: R Score | U5: F Score | V5: M Score | W5: RFM Score | X5: Segment Name | AA5: Customer ID | AB5: Region | AC5: Last Purchase Date | AD5: Day Gap | AE5: Transaction Count | AF5: Total Amount | AG5: R Score | AH5: F Score | AI5: M Score | AJ5: RFM Score | AK5: Segment Name | AN5: Comparison | AP5: Summary | AQ5: Count
B6: T000001 | C6: 45658 | D6: PROD-006 | E6: A4 Printer Paper (500 Sheets) | F6: Office Supplies | G6: 13 | H6: 25000 | I6: 325000 | J6: Customer-190 | K6: Yangon | N6: Customer-002 | O6: Mandalay | P6: =_xlfn.MAXIFS($C$6:$C$2005,$J$6:$J$2005,N6) -> 46016 | Q6: =analysis_date-P6 -> 7 | R6: =COUNTIFS($J$6:$J$2005,N6) -> 3 | S6: =SUMIFS($I$6:$I$2005,$J$6:$J$2005,N6) -> 17425000 | T6: =IF(Q6<MEDIAN($Q$6:$Q$817),"High","Low") -> High | U6: =IF(R6>MEDIAN($R$6:$R$817),"High","Low") -> High | V6: =IF(S6>MEDIAN($S$6:$S$817),"High","Low") -> Low | W6: =_xlfn.CONCAT(LEFT(T6,1),LEFT(U6,1),LEFT(V6,1)) -> HHL | X6: =VLOOKUP(W6,rfm[],2,FALSE) -> 💎 Loyal High Value | Y6: =IF(Q6<MEDIAN($Q$6:$Q$817),"H","L") | AA6: Customer-002 | AB6: Mandalay | AC6: 46016 | AD6: 7 | AE6: 3 | AF6: 17425000 | AG6: =VLOOKUP(AA6,recency!$K$6:$P$818,6,0) -> High | AH6: =VLOOKUP(AA6,frequency!$F$6:$H$818,3,FALSE) -> High | AI6: =VLOOKUP(AA6,monetary!$B$5:$F$817,5,0) -> Low | AJ6: =_xlfn.CONCAT(LEFT(AG6,1),LEFT(AH6,1),LEFT(AI6,1)) -> HHL | AK6: =VLOOKUP(AJ6,rfm[],2,0) -> 💎 Loyal High Value | AN6: =AJ6=W6 -> TRUE | AP6: TRUE | AQ6: =COUNTIFS($AN$6:$AN$817,AP6) -> 454 | AS6: =T6=AG6 -> TRUE
B7: T000002 | C7: 45658 | D7: PROD-006 | E7: A4 Printer Paper (500 Sheets) | F7: Office Supplies | G7: 500 | H7: 25000 | I7: 12500000 | J7: Customer-985 | K7: Bago | N7: Customer-004 | O7: Yangon | P7: =_xlfn.MAXIFS($C$6:$C$2005,$J$6:$J$2005,N7) -> 45965 | Q7: =analysis_date-P7 -> 58 | R7: =COUNTIFS($J$6:$J$2005,N7) -> 5 | S7: =SUMIFS($I$6:$I$2005,$J$6:$J$2005,N7) -> 69590000 | T7: =IF(Q7<MEDIAN($Q$6:$Q$817),"High","Low") -> High | U7: =IF(R7>MEDIAN($R$6:$R$817),"High","Low") -> High | V7: =IF(S7>MEDIAN($S$6:$S$817),"High","Low") -> High | W7: =_xlfn.CONCAT(LEFT(T7,1),LEFT(U7,1),LEFT(V7,1)) -> HHH | X7: =VLOOKUP(W7,rfm[],2,FALSE) -> 🥇 Champions | Y7: =IF(R6>MEDIAN($R$6:$R$817),"H","L") | AA7: Customer-004 | AB7: Yangon | AC7: 45965 | AD7: 58 | AE7: 5 | AF7: 69590000 | AG7: =VLOOKUP(AA7,recency!$K$6:$P$818,6,0) -> High | AH7: =VLOOKUP(AA7,frequency!$F$6:$H$818,3,FALSE) -> High | AI7: =VLOOKUP(AA7,monetary!$B$5:$F$817,5,0) -> High | AJ7: =_xlfn.CONCAT(LEFT(AG7,1),LEFT(AH7,1),LEFT(AI7,1)) -> HHH | AK7: =VLOOKUP(AJ7,rfm[],2,0) -> 🥇 Champions | AN7: =AJ7=W7 -> TRUE | AP7: FALSE | AQ7: =COUNTIFS($AN$6:$AN$817,AP7) -> 358
B8: T000003 | C8: 45658 | D8: PROD-009 | E8: Adjustable Monitor Arm | F8: Furniture | G8: 25 | H8: 180000 | I8: 4500000 | J8: Customer-625 | K8: Mandalay | N8: Customer-005 | O8: Mandalay | P8: =_xlfn.MAXIFS($C$6:$C$2005,$J$6:$J$2005,N8) -> 45922 | Q8: =analysis_date-P8 -> 101 | R8: =COUNTIFS($J$6:$J$2005,N8) -> 2 | S8: =SUMIFS($I$6:$I$2005,$J$6:$J$2005,N8) -> 22950000 | T8: =IF(Q8<MEDIAN($Q$6:$Q$817),"High","Low") -> Low | U8: =IF(R8>MEDIAN($R$6:$R$817),"High","Low") -> Low | V8: =IF(S8>MEDIAN($S$6:$S$817),"High","Low") -> High | W8: =_xlfn.CONCAT(LEFT(T8,1),LEFT(U8,1),LEFT(V8,1)) -> LLH | X8: =VLOOKUP(W8,rfm[],2,FALSE) -> 💸 Lost High Spenders | Y8: =IF(S6>MEDIAN($S$6:$S$817),"H","L") | AA8: Customer-005 | AB8: Mandalay | AC8: 45922 | AD8: 101 | AE8: 2 | AF8: 22950000 | AG8: =VLOOKUP(AA8,recency!$K$6:$P$818,6,0) -> Low | AH8: =VLOOKUP(AA8,frequency!$F$6:$H$818,3,FALSE) -> Low | AI8: =VLOOKUP(AA8,monetary!$B$5:$F$817,5,0) -> Low | AJ8: =_xlfn.CONCAT(LEFT(AG8,1),LEFT(AH8,1),LEFT(AI8,1)) -> LLL | AK8: =VLOOKUP(AJ8,rfm[],2,0) -> 💤 Lost / Low Value | AN8: =AJ8=W8 -> FALSE
B9: T000004 | C9: 45658 | D9: PROD-002 | E9: Wireless Mechanical Keyboard | F9: Electronics | G9: 41 | H9: 350000 | I9: 14350000 | J9: Customer-882 | K9: Yangon | N9: Customer-006 | O9: Bago | P9: =_xlfn.MAXIFS($C$6:$C$2005,$J$6:$J$2005,N9) -> 45722 | Q9: =analysis_date-P9 -> 301 | R9: =COUNTIFS($J$6:$J$2005,N9) -> 1 | S9: =SUMIFS($I$6:$I$2005,$J$6:$J$2005,N9) -> 39900000 | T9: =IF(Q9<MEDIAN($Q$6:$Q$817),"High","Low") -> Low | U9: =IF(R9>MEDIAN($R$6:$R$817),"High","Low") -> Low | V9: =IF(S9>MEDIAN($S$6:$S$817),"High","Low") -> High | W9: =_xlfn.CONCAT(LEFT(T9,1),LEFT(U9,1),LEFT(V9,1)) -> LLH | X9: =VLOOKUP(W9,rfm[],2,FALSE) -> 💸 Lost High Spenders | Y9: =VLOOKUP(W6,rfm,2,0) | AA9: Customer-006 | AB9: Bago | AC9: 45722 | AD9: 301 | AE9: 1 | AF9: 39900000 | AG9: =VLOOKUP(AA9,recency!$K$6:$P$818,6,0) -> Low | AH9: =VLOOKUP(AA9,frequency!$F$6:$H$818,3,FALSE) -> Low | AI9: =VLOOKUP(AA9,monetary!$B$5:$F$817,5,0) -> Low | AJ9: =_xlfn.CONCAT(LEFT(AG9,1),LEFT(AH9,1),LEFT(AI9,1)) -> LLL | AK9: =VLOOKUP(AJ9,rfm[],2,0) -> 💤 Lost / Low Value | AN9: =AJ9=W9 -> FALSE
B10: T000005 | C10: 45658 | D10: PROD-009 | E10: Adjustable Monitor Arm | F10: Furniture | G10: 28 | H10: 180000 | I10: 5040000 | J10: Customer-801 | K10: Bago | N10: Customer-007 | O10: Bago | P10: =_xlfn.MAXIFS($C$6:$C$2005,$J$6:$J$2005,N10) -> 45834 | Q10: =analysis_date-P10 -> 189 | R10: =COUNTIFS($J$6:$J$2005,N10) -> 1 | S10: =SUMIFS($I$6:$I$2005,$J$6:$J$2005,N10) -> 250000 | T10: =IF(Q10<MEDIAN($Q$6:$Q$817),"High","Low") -> Low | U10: =IF(R10>MEDIAN($R$6:$R$817),"High","Low") -> Low | V10: =IF(S10>MEDIAN($S$6:$S$817),"High","Low") -> Low | W10: =_xlfn.CONCAT(LEFT(T10,1),LEFT(U10,1),LEFT(V10,1)) -> LLL | X10: =VLOOKUP(W10,rfm[],2,FALSE) -> 💤 Lost / Low Value | AA10: Customer-007 | AB10: Bago | AC10: 45834 | AD10: 189 | AE10: 1 | AF10: 250000 | AG10: =VLOOKUP(AA10,recency!$K$6:$P$818,6,0) -> Low | AH10: =VLOOKUP(AA10,frequency!$F$6:$H$818,3,FALSE) -> Low | AI10: =VLOOKUP(AA10,monetary!$B$5:$F$817,5,0) -> Low | AJ10: =_xlfn.CONCAT(LEFT(AG10,1),LEFT(AH10,1),LEFT(AI10,1)) -> LLL | AK10: =VLOOKUP(AJ10,rfm[],2,0) -> 💤 Lost / Low Value | AN10: =AJ10=W10 -> TRUE
B11: T000006 | C11: 45658 | D11: PROD-007 | E11: USB-C Docking Station | F11: Electronics | G11: 7 | H11: 250000 | I11: 1750000 | J11: Customer-666 | K11: Yangon | N11: Customer-008 | O11: Bago | P11: =_xlfn.MAXIFS($C$6:$C$2005,$J$6:$J$2005,N11) -> 45727 | Q11: =analysis_date-P11 -> 296 | R11: =COUNTIFS($J$6:$J$2005,N11) -> 1 | S11: =SUMIFS($I$6:$I$2005,$J$6:$J$2005,N11) -> 19000000 | T11: =IF(Q11<MEDIAN($Q$6:$Q$817),"High","Low") -> Low | U11: =IF(R11>MEDIAN($R$6:$R$817),"High","Low") -> Low | V11: =IF(S11>MEDIAN($S$6:$S$817),"High","Low") -> High | W11: =_xlfn.CONCAT(LEFT(T11,1),LEFT(U11,1),LEFT(V11,1)) -> LLH | X11: =VLOOKUP(W11,rfm[],2,FALSE) -> 💸 Lost High Spenders | AA11: Customer-008 | AB11: Bago | AC11: 45727 | AD11: 296 | AE11: 1 | AF11: 19000000 | AG11: =VLOOKUP(AA11,recency!$K$6:$P$818,6,0) -> Low | AH11: =VLOOKUP(AA11,frequency!$F$6:$H$818,3,FALSE) -> Low | AI11: =VLOOKUP(AA11,monetary!$B$5:$F$817,5,0) -> Low | AJ11: =_xlfn.CONCAT(LEFT(AG11,1),LEFT(AH11,1),LEFT(AI11,1)) -> LLL | AK11: =VLOOKUP(AJ11,rfm[],2,0) -> 💤 Lost / Low Value | AN11: =AJ11=W11 -> FALSE
B12: T000007 | C12: 45658 | D12: PROD-009 | E12: Adjustable Monitor Arm | F12: Furniture | G12: 35 | H12: 180000 | I12: 6300000 | J12: Customer-999 | K12: Naypyitaw | N12: Customer-009 | O12: Mandalay | P12: =_xlfn.MAXIFS($C$6:$C$2005,$J$6:$J$2005,N12) -> 45768 | Q12: =analysis_date-P12 -> 255 | R12: =COUNTIFS($J$6:$J$2005,N12) -> 2 | S12: =SUMIFS($I$6:$I$2005,$J$6:$J$2005,N12) -> 11700000 | T12: =IF(Q12<MEDIAN($Q$6:$Q$817),"High","Low") -> Low | U12: =IF(R12>MEDIAN($R$6:$R$817),"High","Low") -> Low | V12: =IF(S12>MEDIAN($S$6:$S$817),"High","Low") -> Low | W12: =_xlfn.CONCAT(LEFT(T12,1),LEFT(U12,1),LEFT(V12,1)) -> LLL | X12: =VLOOKUP(W12,rfm[],2,FALSE) -> 💤 Lost / Low Value | AA12: Customer-009 | AB12: Mandalay | AC12: 45768 | AD12: 255 | AE12: 2 | AF12: 11700000 | AG12: =VLOOKUP(AA12,recency!$K$6:$P$818,6,0) -> Low | AH12: =VLOOKUP(AA12,frequency!$F$6:$H$818,3,FALSE) -> Low | AI12: =VLOOKUP(AA12,monetary!$B$5:$F$817,5,0) -> Low | AJ12: =_xlfn.CONCAT(LEFT(AG12,1),LEFT(AH12,1),LEFT(AI12,1)) -> LLL | AK12: =VLOOKUP(AJ12,rfm[],2,0) -> 💤 Lost / Low Value | AN12: =AJ12=W12 -> TRUE
B13: T000008 | C13: 45658 | D13: PROD-008 | E13: Executive Ballpoint Pen Box | F13: Office Supplies | G13: 21 | H13: 120000 | I13: 2520000 | J13: Customer-364 | K13: Taunggyi | N13: Customer-012 | O13: Mandalay | P13: =_xlfn.MAXIFS($C$6:$C$2005,$J$6:$J$2005,N13) -> 45950 | Q13: =analysis_date-P13 -> 73 | R13: =COUNTIFS($J$6:$J$2005,N13) -> 3 | S13: =SUMIFS($I$6:$I$2005,$J$6:$J$2005,N13) -> 10230000 | T13: =IF(Q13<MEDIAN($Q$6:$Q$817),"High","Low") -> High | U13: =IF(R13>MEDIAN($R$6:$R$817),"High","Low") -> High | V13: =IF(S13>MEDIAN($S$6:$S$817),"High","Low") -> Low | W13: =_xlfn.CONCAT(LEFT(T13,1),LEFT(U13,1),LEFT(V13,1)) -> HHL | X13: =VLOOKUP(W13,rfm[],2,FALSE) -> 💎 Loyal High Value | AA13: Customer-012 | AB13: Mandalay | AC13: 45950 | AD13: 73 | AE13: 3 | AF13: 10230000 | AG13: =VLOOKUP(AA13,recency!$K$6:$P$818,6,0) -> Low | AH13: =VLOOKUP(AA13,frequency!$F$6:$H$818,3,FALSE) -> High | AI13: =VLOOKUP(AA13,monetary!$B$5:$F$817,5,0) -> Low | AJ13: =_xlfn.CONCAT(LEFT(AG13,1),LEFT(AH13,1),LEFT(AI13,1)) -> LHL | AK13: =VLOOKUP(AJ13,rfm[],2,0) -> 🔁 Former Loyal Low Spend | AN13: =AJ13=W13 -> FALSE
B14: T000009 | C14: 45658 | D14: PROD-007 | E14: USB-C Docking Station | F14: Electronics | G14: 32 | H14: 250000 | I14: 8000000 | J14: Customer-803 | K14: Taunggyi | N14: Customer-013 | O14: Yangon | P14: =_xlfn.MAXIFS($C$6:$C$2005,$J$6:$J$2005,N14) -> 45978 | Q14: =analysis_date-P14 -> 45 | R14: =COUNTIFS($J$6:$J$2005,N14) -> 3 | S14: =SUMIFS($I$6:$I$2005,$J$6:$J$2005,N14) -> 60960000 | T14: =IF(Q14<MEDIAN($Q$6:$Q$817),"High","Low") -> High | U14: =IF(R14>MEDIAN($R$6:$R$817),"High","Low") -> High | V14: =IF(S14>MEDIAN($S$6:$S$817),"High","Low") -> High | W14: =_xlfn.CONCAT(LEFT(T14,1),LEFT(U14,1),LEFT(V14,1)) -> HHH | X14: =VLOOKUP(W14,rfm[],2,FALSE) -> 🥇 Champions | AA14: Customer-013 | AB14: Yangon | AC14: 45978 | AD14: 45 | AE14: 3 | AF14: 60960000 | AG14: =VLOOKUP(AA14,recency!$K$6:$P$818,6,0) -> High | AH14: =VLOOKUP(AA14,frequency!$F$6:$H$818,3,FALSE) -> High | AI14: =VLOOKUP(AA14,monetary!$B$5:$F$817,5,0) -> High | AJ14: =_xlfn.CONCAT(LEFT(AG14,1),LEFT(AH14,1),LEFT(AI14,1)) -> HHH | AK14: =VLOOKUP(AJ14,rfm[],2,0) -> 🥇 Champions | AN14: =AJ14=W14 -> TRUE
B15: T000010 | C15: 45659 | D15: PROD-002 | E15: Wireless Mechanical Keyboard | F15: Electronics | G15: 21 | H15: 350000 | I15: 7350000 | J15: Customer-931 | K15: Yangon | N15: Customer-014 | O15: Mandalay | P15: =_xlfn.MAXIFS($C$6:$C$2005,$J$6:$J$2005,N15) -> 45924 | Q15: =analysis_date-P15 -> 99 | R15: =COUNTIFS($J$6:$J$2005,N15) -> 1 | S15: =SUMIFS($I$6:$I$2005,$J$6:$J$2005,N15) -> 18450000 | T15: =IF(Q15<MEDIAN($Q$6:$Q$817),"High","Low") -> Low | U15: =IF(R15>MEDIAN($R$6:$R$817),"High","Low") -> Low | V15: =IF(S15>MEDIAN($S$6:$S$817),"High","Low") -> High | W15: =_xlfn.CONCAT(LEFT(T15,1),LEFT(U15,1),LEFT(V15,1)) -> LLH | X15: =VLOOKUP(W15,rfm[],2,FALSE) -> 💸 Lost High Spenders | AA15: Customer-014 | AB15: Mandalay | AC15: 45924 | AD15: 99 | AE15: 1 | AF15: 18450000 | AG15: =VLOOKUP(AA15,recency!$K$6:$P$818,6,0) -> Low | AH15: =VLOOKUP(AA15,frequency!$F$6:$H$818,3,FALSE) -> Low | AI15: =VLOOKUP(AA15,monetary!$B$5:$F$817,5,0) -> Low | AJ15: =_xlfn.CONCAT(LEFT(AG15,1),LEFT(AH15,1),LEFT(AI15,1)) -> LLL | AK15: =VLOOKUP(AJ15,rfm[],2,0) -> 💤 Lost / Low Value | AN15: =AJ15=W15 -> FALSE
B16: T000011 | C16: 45659 | D16: PROD-003 | E16: 27-inch 4K Monitor | F16: Electronics | G16: 30 | H16: 1200000 | I16: 36000000 | J16: Customer-469 | K16: Taunggyi | N16: Customer-015 | O16: Naypyitaw | P16: =_xlfn.MAXIFS($C$6:$C$2005,$J$6:$J$2005,N16) -> 45854 | Q16: =analysis_date-P16 -> 169 | R16: =COUNTIFS($J$6:$J$2005,N16) -> 1 | S16: =SUMIFS($I$6:$I$2005,$J$6:$J$2005,N16) -> 18500000 | T16: =IF(Q16<MEDIAN($Q$6:$Q$817),"High","Low") -> Low | U16: =IF(R16>MEDIAN($R$6:$R$817),"High","Low") -> Low | V16: =IF(S16>MEDIAN($S$6:$S$817),"High","Low") -> High | W16: =_xlfn.CONCAT(LEFT(T16,1),LEFT(U16,1),LEFT(V16,1)) -> LLH | X16: =VLOOKUP(W16,rfm[],2,FALSE) -> 💸 Lost High Spenders | AA16: Customer-015 | AB16: Naypyitaw | AC16: 45854 | AD16: 169 | AE16: 1 | AF16: 18500000 | AG16: =VLOOKUP(AA16,recency!$K$6:$P$818,6,0) -> Low | AH16: =VLOOKUP(AA16,frequency!$F$6:$H$818,3,FALSE) -> Low | AI16: =VLOOKUP(AA16,monetary!$B$5:$F$817,5,0) -> Low | AJ16: =_xlfn.CONCAT(LEFT(AG16,1),LEFT(AH16,1),LEFT(AI16,1)) -> LLL | AK16: =VLOOKUP(AJ16,rfm[],2,0) -> 💤 Lost / Low Value | AN16: =AJ16=W16 -> FALSE
B17: T000012 | C17: 45659 | D17: PROD-004 | E17: Standing Desk Converter | F17: Furniture | G17: 12 | H17: 500000 | I17: 6000000 | J17: Customer-822 | K17: Naypyitaw | N17: Customer-016 | O17: Taunggyi | P17: =_xlfn.MAXIFS($C$6:$C$2005,$J$6:$J$2005,N17) -> 45904 | Q17: =analysis_date-P17 -> 119 | R17: =COUNTIFS($J$6:$J$2005,N17) -> 3 | S17: =SUMIFS($I$6:$I$2005,$J$6:$J$2005,N17) -> 43550000 | T17: =IF(Q17<MEDIAN($Q$6:$Q$817),"High","Low") -> Low | U17: =IF(R17>MEDIAN($R$6:$R$817),"High","Low") -> High | V17: =IF(S17>MEDIAN($S$6:$S$817),"High","Low") -> High | W17: =_xlfn.CONCAT(LEFT(T17,1),LEFT(U17,1),LEFT(V17,1)) -> LHH | X17: =VLOOKUP(W17,rfm[],2,FALSE) -> ⚠️ At Risk High Value | AA17: Customer-016 | AB17: Taunggyi | AC17: 45904 | AD17: 119 | AE17: 3 | AF17: 43550000 | AG17: =VLOOKUP(AA17,recency!$K$6:$P$818,6,0) -> Low | AH17: =VLOOKUP(AA17,frequency!$F$6:$H$818,3,FALSE) -> High | AI17: =VLOOKUP(AA17,monetary!$B$5:$F$817,5,0) -> Low | AJ17: =_xlfn.CONCAT(LEFT(AG17,1),LEFT(AH17,1),LEFT(AI17,1)) -> LHL | AK17: =VLOOKUP(AJ17,rfm[],2,0) -> 🔁 Former Loyal Low Spend | AN17: =AJ17=W17 -> FALSE
B18: T000013 | C18: 45659 | D18: PROD-009 | E18: Adjustable Monitor Arm | F18: Furniture | G18: 17 | H18: 180000 | I18: 3060000 | J18: Customer-151 | K18: Mandalay | N18: Customer-017 | O18: Yangon | P18: =_xlfn.MAXIFS($C$6:$C$2005,$J$6:$J$2005,N18) -> 45790 | Q18: =analysis_date-P18 -> 233 | R18: =COUNTIFS($J$6:$J$2005,N18) -> 3 | S18: =SUMIFS($I$6:$I$2005,$J$6:$J$2005,N18) -> 22350000 | T18: =IF(Q18<MEDIAN($Q$6:$Q$817),"High","Low") -> Low | U18: =IF(R18>MEDIAN($R$6:$R$817),"High","Low") -> High | V18: =IF(S18>MEDIAN($S$6:$S$817),"High","Low") -> High | W18: =_xlfn.CONCAT(LEFT(T18,1),LEFT(U18,1),LEFT(V18,1)) -> LHH | X18: =VLOOKUP(W18,rfm[],2,FALSE) -> ⚠️ At Risk High Value | AA18: Customer-017 | AB18: Yangon | AC18: 45790 | AD18: 233 | AE18: 3 | AF18: 22350000 | AG18: =VLOOKUP(AA18,recency!$K$6:$P$818,6,0) -> Low | AH18: =VLOOKUP(AA18,frequency!$F$6:$H$818,3,FALSE) -> High | AI18: =VLOOKUP(AA18,monetary!$B$5:$F$817,5,0) -> Low | AJ18: =_xlfn.CONCAT(LEFT(AG18,1),LEFT(AH18,1),LEFT(AI18,1)) -> LHL | AK18: =VLOOKUP(AJ18,rfm[],2,0) -> 🔁 Former Loyal Low Spend | AN18: =AJ18=W18 -> FALSE
B19: T000014 | C19: 45659 | D19: PROD-010 | E19: Webcam 1080p HD | F19: Electronics | G19: 35 | H19: 200000 | I19: 7000000 | J19: Customer-904 | K19: Mandalay | N19: Customer-019 | O19: Bago | P19: =_xlfn.MAXIFS($C$6:$C$2005,$J$6:$J$2005,N19) -> 45940 | Q19: =analysis_date-P19 -> 83 | R19: =COUNTIFS($J$6:$J$2005,N19) -> 3 | S19: =SUMIFS($I$6:$I$2005,$J$6:$J$2005,N19) -> 5825000 | T19: =IF(Q19<MEDIAN($Q$6:$Q$817),"High","Low") -> High | U19: =IF(R19>MEDIAN($R$6:$R$817),"High","Low") -> High | V19: =IF(S19>MEDIAN($S$6:$S$817),"High","Low") -> Low | W19: =_xlfn.CONCAT(LEFT(T19,1),LEFT(U19,1),LEFT(V19,1)) -> HHL | X19: =VLOOKUP(W19,rfm[],2,FALSE) -> 💎 Loyal High Value | AA19: Customer-019 | AB19: Bago | AC19: 45940 | AD19: 83 | AE19: 3 | AF19: 5825000 | AG19: =VLOOKUP(AA19,recency!$K$6:$P$818,6,0) -> Low | AH19: =VLOOKUP(AA19,frequency!$F$6:$H$818,3,FALSE) -> High | AI19: =VLOOKUP(AA19,monetary!$B$5:$F$817,5,0) -> Low | AJ19: =_xlfn.CONCAT(LEFT(AG19,1),LEFT(AH19,1),LEFT(AI19,1)) -> LHL | AK19: =VLOOKUP(AJ19,rfm[],2,0) -> 🔁 Former Loyal Low Spend | AN19: =AJ19=W19 -> FALSE
B20: T000015 | C20: 45659 | D20: PROD-005 | E20: Noise-Cancelling Headphones | F20: Electronics | G20: 400 | H20: 950000 | I20: 380000000 | J20: Customer-732 | K20: Naypyitaw | N20: Customer-020 | O20: Yangon | P20: =_xlfn.MAXIFS($C$6:$C$2005,$J$6:$J$2005,N20) -> 45986 | Q20: =analysis_date-P20 -> 37 | R20: =COUNTIFS($J$6:$J$2005,N20) -> 5 | S20: =SUMIFS($I$6:$I$2005,$J$6:$J$2005,N20) -> 38710000 | T20: =IF(Q20<MEDIAN($Q$6:$Q$817),"High","Low") -> High | U20: =IF(R20>MEDIAN($R$6:$R$817),"High","Low") -> High | V20: =IF(S20>MEDIAN($S$6:$S$817),"High","Low") -> High | W20: =_xlfn.CONCAT(LEFT(T20,1),LEFT(U20,1),LEFT(V20,1)) -> HHH | X20: =VLOOKUP(W20,rfm[],2,FALSE) -> 🥇 Champions | AA20: Customer-020 | AB20: Yangon | AC20: 45986 | AD20: 37 | AE20: 5 | AF20: 38710000 | AG20: =VLOOKUP(AA20,recency!$K$6:$P$818,6,0) -> High | AH20: =VLOOKUP(AA20,frequency!$F$6:$H$818,3,FALSE) -> High | AI20: =VLOOKUP(AA20,monetary!$B$5:$F$817,5,0) -> Low | AJ20: =_xlfn.CONCAT(LEFT(AG20,1),LEFT(AH20,1),LEFT(AI20,1)) -> HHL | AK20: =VLOOKUP(AJ20,rfm[],2,0) -> 💎 Loyal High Value | AN20: =AJ20=W20 -> FALSE
B21: T000016 | C21: 45659 | D21: PROD-003 | E21: 27-inch 4K Monitor | F21: Electronics | G21: 24 | H21: 1200000 | I21: 28800000 | J21: Customer-199 | K21: Yangon | N21: Customer-021 | O21: Taunggyi | P21: =_xlfn.MAXIFS($C$6:$C$2005,$J$6:$J$2005,N21) -> 46015 | Q21: =analysis_date-P21 -> 8 | R21: =COUNTIFS($J$6:$J$2005,N21) -> 2 | S21: =SUMIFS($I$6:$I$2005,$J$6:$J$2005,N21) -> 57550000 | T21: =IF(Q21<MEDIAN($Q$6:$Q$817),"High","Low") -> High | U21: =IF(R21>MEDIAN($R$6:$R$817),"High","Low") -> Low | V21: =IF(S21>MEDIAN($S$6:$S$817),"High","Low") -> High | W21: =_xlfn.CONCAT(LEFT(T21,1),LEFT(U21,1),LEFT(V21,1)) -> HLH | X21: =VLOOKUP(W21,rfm[],2,FALSE) -> 🛒 Big Spenders (Occasional) | AA21: Customer-021 | AB21: Taunggyi | AC21: 46015 | AD21: 8 | AE21: 2 | AF21: 57550000 | AG21: =VLOOKUP(AA21,recency!$K$6:$P$818,6,0) -> High | AH21: =VLOOKUP(AA21,frequency!$F$6:$H$818,3,FALSE) -> Low | AI21: =VLOOKUP(AA21,monetary!$B$5:$F$817,5,0) -> High | AJ21: =_xlfn.CONCAT(LEFT(AG21,1),LEFT(AH21,1),LEFT(AI21,1)) -> HLH | AK21: =VLOOKUP(AJ21,rfm[],2,0) -> 🛒 Big Spenders (Occasional) | AN21: =AJ21=W21 -> TRUE
... B817: T000812 | C817: 45807 | D817: PROD-002 | E817: Wireless Mechanical Keyboard | F817: Electronics | G817: 35 | H817: 350000 | I817: 12250000 | J817: Customer-625 | K817: Mandalay | N817: Customer-999 | O817: Naypyitaw | P817: =_xlfn.MAXIFS($C$6:$C$2005,$J$6:$J$2005,N817) -> 45855 | Q817: =analysis_date-P817 -> 168 | R817: =COUNTIFS($J$6:$J$2005,N817) -> 2 | S817: =SUMIFS($I$6:$I$2005,$J$6:$J$2005,N817) -> 10800000 | T817: =IF(Q817<MEDIAN($Q$6:$Q$817),"High","Low") -> Low | U817: =IF(R817>MEDIAN($R$6:$R$817),"High","Low") -> Low | V817: =IF(S817>MEDIAN($S$6:$S$817),"High","Low") -> Low | W817: =_xlfn.CONCAT(LEFT(T817,1),LEFT(U817,1),LEFT(V817,1)) -> LLL | X817: =VLOOKUP(W817,rfm[],2,FALSE) -> 💤 Lost / Low Value | AA817: Customer-999 | AB817: Naypyitaw | AC817: 45855 | AD817: 168 | AE817: 2 | AF817: 10800000 | AG817: =VLOOKUP(AA817,recency!$K$6:$P$818,6,0) -> Low | AH817: =VLOOKUP(AA817,frequency!$F$6:$H$818,3,FALSE) -> Low | AI817: =VLOOKUP(AA817,monetary!$B$5:$F$817,5,0) -> Low | AJ817: =_xlfn.CONCAT(LEFT(AG817,1),LEFT(AH817,1),LEFT(AI817,1)) -> LLL | AK817: =VLOOKUP(AJ817,rfm[],2,0) -> 💤 Lost / Low Value | AN817: =AJ817=W817 -> TRUE
B818: T000813 | C818: 45807 | D818: PROD-010 | E818: Webcam 1080p HD | F818: Electronics | G818: 28 | H818: 200000 | I818: 5600000 | J818: Customer-912 | K818: Yangon | AF818: =SUM(AF6:AF817) -> 59851600000
B819: T000814 | C819: 45807 | D819: PROD-002 | E819: Wireless Mechanical Keyboard | F819: Electronics | G819: 160 | H819: 350000 | I819: 56000000 | J819: Customer-410 | K819: Yangon | AF819: 59851600000
B820: T000815 | C820: 45807 | D820: PROD-002 | E820: Wireless Mechanical Keyboard | F820: Electronics | G820: 15 | H820: 350000 | I820: 5250000 | J820: Customer-318 | K820: Taunggyi
B821: T000816 | C821: 45807 | D821: PROD-005 | E821: Noise-Cancelling Headphones | F821: Electronics | G821: 7 | H821: 950000 | I821: 6650000 | J821: Customer-828 | K821: Mandalay
B822: T000817 | C822: 45807 | D822: PROD-007 | E822: USB-C Docking Station | F822: Electronics | G822: 100 | H822: 250000 | I822: 25000000 | J822: Customer-918 | K822: Yangon
B823: T000818 | C823: 45807 | D823: PROD-002 | E823: Wireless Mechanical Keyboard | F823: Electronics | G823: 21 | H823: 350000 | I823: 7350000 | J823: Customer-954 | K823: Bago
B824: T000819 | C824: 45807 | D824: PROD-009 | E824: Adjustable Monitor Arm | F824: Furniture | G824: 24 | H824: 180000 | I824: 4320000 | J824: Customer-683 | K824: Naypyitaw
B825: T000820 | C825: 45807 | D825: PROD-006 | E825: A4 Printer Paper (500 Sheets) | F825: Office Supplies | G825: 150 | H825: 25000 | I825: 3750000 | J825: Customer-180 | K825: Mandalay
B826: T000821 | C826: 45807 | D826: PROD-008 | E826: Executive Ballpoint Pen Box | F826: Office Supplies | G826: 13 | H826: 120000 | I826: 1560000 | J826: Customer-068 | K826: Taunggyi
B827: T000822 | C827: 45807 | D827: PROD-005 | E827: Noise-Cancelling Headphones | F827: Electronics | G827: 44 | H827: 950000 | I827: 41800000 | J827: Customer-754 | K827: Naypyitaw
B828: T000823 | C828: 45807 | D828: PROD-008 | E828: Executive Ballpoint Pen Box | F828: Office Supplies | G828: 36 | H828: 120000 | I828: 4320000 | J828: Customer-383 | K828: Yangon
B829: T000824 | C829: 45807 | D829: PROD-007 | E829: USB-C Docking Station | F829: Electronics | G829: 29 | H829: 250000 | I829: 7250000 | J829: Customer-274 | K829: Mandalay
B830: T000825 | C830: 45812 | D830: PROD-001 | E830: Ergonomic Mesh Chair | F830: Furniture | G830: 46 | H830: 450000 | I830: 20700000 | J830: Customer-839 | K830: Mandalay
B831: T000826 | C831: 45812 | D831: PROD-007 | E831: USB-C Docking Station | F831: Electronics | G831: 25 | H831: 250000 | I831: 6250000 | J831: Customer-473 | K831: Taunggyi
... B2005: T002000 | C2005: 46022 | D2005: PROD-007 | E2005: USB-C Docking Station | F2005: Electronics | G2005: 11 | H2005: 250000 | I2005: 2750000 | J2005: Customer-126 | K2005: Yangon

Sheet recency
A1: User CMA Smart & Secure : Applied Data Analytics Training Center.
A2: http://www.facebook.com/cma.01012020
A3: Email: info@usercma.com Phone: 09 44717 2115
H4: Returned = 1 if next purchase ≤ 30 days
F5: =IF(D7=D8,E8,"") | G5: =IF(F7="","",F7-E7) | H5: =IFS(G7="","",G7<=return_window,1,1,0) | L5: Did each customer EVER return within 30 days? | V5: Look for the Pattern (NOT the numbers)
A6: Analysis Date | D6: Customer ID | E6: Date | F6: Next Purchase Date | G6: Date Gap | H6: Returned | K6: Customer ID | L6: Returned ? | M6: Last Purchase Date | N6: Recency | O6: Returned Bucket | P6: R Score | S6: Returned Bucket | T6: Customers | U6: Returned Customers | V6: Return Rate | W6: % Gap
A7: 46023 | D7: Customer-002 | E7: 45771 | F7: =IF(D7=D8,E8,"") -> 46000 | G7: =IF(F7="","",F7-E7) -> 229 | H7: =IF(G7="","",IF(G7<=return_window,1,0)) -> 0 | K7: Customer-002 | L7: =IF(SUMIFS($H$6:$H$2006,$D$6:$D$2006,K7),1,0) -> 1 | M7: 46016 | N7: 7 | O7: =VLOOKUP(N7,$A$15:$B$19,2,TRUE) -> 0-30 | P7: =IF(N7<=recency_threshold,"High","Low") -> High | S7: 0-30 | T7: =COUNTIFS(O$7:O$818,S7) -> 153 | U7: =COUNTIFS($O$7:$O$818,S7,$L$7:$L$818,1) -> 61 | V7: =U7/T7 -> 0.39869281
D8: Customer-002 | E8: 46000 | F8: =IF(D8=D9,E9,"") -> 46016 | G8: =IF(F8="","",F8-E8) -> 16 | H8: =IF(G8="","",IF(G8<=return_window,1,0)) -> 1 | K8: Customer-004 | L8: =IF(SUMIFS($H$6:$H$2006,$D$6:$D$2006,K8),1,0) -> 1 | M8: 45965 | N8: 58 | O8: =VLOOKUP(N8,$A$15:$B$19,2,TRUE) -> 31-60 | P8: =IF(N8<=recency_threshold,"High","Low") -> High | S8: 31-60 | T8: =COUNTIFS(O$7:O$818,S8) -> 127 | U8: =COUNTIFS($O$7:$O$818,S8,$L$7:$L$818,1) -> 51 | V8: =U8/T8 -> 0.4015748 | W8: =V8-V7 -> 0.0028819927
A9: Return Window | D9: Customer-002 | E9: 46016 | F9: =IF(D9=D10,E10,"") | G9: =IF(F9="","",F9-E9) | H9: =IF(G9="","",IF(G9<=return_window,1,0)) | K9: Customer-005 | L9: =IF(SUMIFS($H$6:$H$2006,$D$6:$D$2006,K9),1,0) -> 0 | M9: 45922 | N9: 101 | O9: =VLOOKUP(N9,$A$15:$B$19,2,TRUE) -> 90+ | P9: =IF(N9<=recency_threshold,"High","Low") -> Low | S9: 61-90 | T9: =COUNTIFS(O$7:O$818,S9) -> 109 | U9: =COUNTIFS($O$7:$O$818,S9,$L$7:$L$818,1) -> 30 | V9: =U9/T9 -> 0.27522936 | W9: =V9-V8 -> -0.12634545
A10: 30 | D10: Customer-004 | E10: 45782 | F10: =IF(D10=D11,E11,"") -> 45825 | G10: =IF(F10="","",F10-E10) -> 43 | H10: =IF(G10="","",IF(G10<=return_window,1,0)) -> 0 | K10: Customer-006 | L10: =IF(SUMIFS($H$6:$H$2006,$D$6:$D$2006,K10),1,0) -> 0 | M10: 45722 | N10: 301 | O10: =VLOOKUP(N10,$A$15:$B$19,2,TRUE) -> 90+ | P10: =IF(N10<=recency_threshold,"High","Low") -> Low | S10: 90+ | T10: =COUNTIFS(O$7:O$818,S10) -> 423 | U10: =COUNTIFS($O$7:$O$818,S10,$L$7:$L$818,1) -> 86 | V10: =U10/T10 -> 0.20330969 | W10: =V10-V9 -> -0.071919665
D11: Customer-004 | E11: 45825 | F11: =IF(D11=D12,E12,"") -> 45909 | G11: =IF(F11="","",F11-E11) -> 84 | H11: =IF(G11="","",IF(G11<=return_window,1,0)) -> 0 | K11: Customer-007 | L11: =IF(SUMIFS($H$6:$H$2006,$D$6:$D$2006,K11),1,0) -> 0 | M11: 45834 | N11: 189 | O11: =VLOOKUP(N11,$A$15:$B$19,2,TRUE) -> 90+ | P11: =IF(N11<=recency_threshold,"High","Low") -> Low
A12: Recency Threshold | D12: Customer-004 | E12: 45909 | F12: =IF(D12=D13,E13,"") -> 45923 | G12: =IF(F12="","",F12-E12) -> 14 | H12: =IF(G12="","",IF(G12<=return_window,1,0)) -> 1 | K12: Customer-008 | L12: =IF(SUMIFS($H$6:$H$2006,$D$6:$D$2006,K12),1,0) -> 0 | M12: 45727 | N12: 296 | O12: =VLOOKUP(N12,$A$15:$B$19,2,TRUE) -> 90+ | P12: =IF(N12<=recency_threshold,"High","Low") -> Low
A13: 60 | D13: Customer-004 | E13: 45923 | F13: =IF(D13=D14,E14,"") -> 45965 | G13: =IF(F13="","",F13-E13) -> 42 | H13: =IF(G13="","",IF(G13<=return_window,1,0)) -> 0 | K13: Customer-009 | L13: =IF(SUMIFS($H$6:$H$2006,$D$6:$D$2006,K13),1,0) -> 1 | M13: 45768 | N13: 255 | O13: =VLOOKUP(N13,$A$15:$B$19,2,TRUE) -> 90+ | P13: =IF(N13<=recency_threshold,"High","Low") -> Low
D14: Customer-004 | E14: 45965 | F14: =IF(D14=D15,E15,"") | G14: =IF(F14="","",F14-E14) | H14: =IF(G14="","",IF(G14<=return_window,1,0)) | K14: Customer-012 | L14: =IF(SUMIFS($H$6:$H$2006,$D$6:$D$2006,K14),1,0) -> 0 | M14: 45950 | N14: 73 | O14: =VLOOKUP(N14,$A$15:$B$19,2,TRUE) -> 61-90 | P14: =IF(N14<=recency_threshold,"High","Low") -> Low
A15: lookup_value | B15: Returned Bucket | D15: Customer-005 | E15: 45848 | F15: =IF(D15=D16,E16,"") -> 45922 | G15: =IF(F15="","",F15-E15) -> 74 | H15: =IF(G15="","",IF(G15<=return_window,1,0)) -> 0 | K15: Customer-013 | L15: =IF(SUMIFS($H$6:$H$2006,$D$6:$D$2006,K15),1,0) -> 0 | M15: 45978 | N15: 45 | O15: =VLOOKUP(N15,$A$15:$B$19,2,TRUE) -> 31-60 | P15: =IF(N15<=recency_threshold,"High","Low") -> High
A16: 0 | B16: 0-30 | D16: Customer-005 | E16: 45922 | F16: =IF(D16=D17,E17,"") | G16: =IF(F16="","",F16-E16) | H16: =IF(G16="","",IF(G16<=return_window,1,0)) | K16: Customer-014 | L16: =IF(SUMIFS($H$6:$H$2006,$D$6:$D$2006,K16),1,0) -> 0 | M16: 45924 | N16: 99 | O16: =VLOOKUP(N16,$A$15:$B$19,2,TRUE) -> 90+ | P16: =IF(N16<=recency_threshold,"High","Low") -> Low
A17: 31 | B17: 31-60 | D17: Customer-006 | E17: 45722 | F17: =IF(D17=D18,E18,"") | G17: =IF(F17="","",F17-E17) | H17: =IF(G17="","",IF(G17<=return_window,1,0)) | K17: Customer-015 | L17: =IF(SUMIFS($H$6:$H$2006,$D$6:$D$2006,K17),1,0) -> 0 | M17: 45854 | N17: 169 | O17: =VLOOKUP(N17,$A$15:$B$19,2,TRUE) -> 90+ | P17: =IF(N17<=recency_threshold,"High","Low") -> Low
A18: 61 | B18: 61-90 | D18: Customer-007 | E18: 45834 | F18: =IF(D18=D19,E19,"") | G18: =IF(F18="","",F18-E18) | H18: =IF(G18="","",IF(G18<=return_window,1,0)) | K18: Customer-016 | L18: =IF(SUMIFS($H$6:$H$2006,$D$6:$D$2006,K18),1,0) -> 0 | M18: 45904 | N18: 119 | O18: =VLOOKUP(N18,$A$15:$B$19,2,TRUE) -> 90+ | P18: =IF(N18<=recency_threshold,"High","Low") -> Low
A19: 91 | B19: 90+ | D19: Customer-008 | E19: 45727 | F19: =IF(D19=D20,E20,"") | G19: =IF(F19="","",F19-E19) | H19: =IF(G19="","",IF(G19<=return_window,1,0)) | K19: Customer-017 | L19: =IF(SUMIFS($H$6:$H$2006,$D$6:$D$2006,K19),1,0) -> 0 | M19: 45790 | N19: 233 | O19: =VLOOKUP(N19,$A$15:$B$19,2,TRUE) -> 90+ | P19: =IF(N19<=recency_threshold,"High","Low") -> Low
D20: Customer-009 | E20: 45754 | F20: =IF(D20=D21,E21,"") -> 45768 | G20: =IF(F20="","",F20-E20) -> 14 | H20: =IF(G20="","",IF(G20<=return_window,1,0)) -> 1 | K20: Customer-019 | L20: =IF(SUMIFS($H$6:$H$2006,$D$6:$D$2006,K20),1,0) -> 1 | M20: 45940 | N20: 83 | O20: =VLOOKUP(N20,$A$15:$B$19,2,TRUE) -> 61-90 | P20: =IF(N20<=recency_threshold,"High","Low") -> Low
D21: Customer-009 | E21: 45768 | F21: =IF(D21=D22,E22,"") | G21: =IF(F21="","",F21-E21) | H21: =IF(G21="","",IF(G21<=return_window,1,0)) | K21: Customer-020 | L21: =IF(SUMIFS($H$6:$H$2006,$D$6:$D$2006,K21),1,0) -> 1 | M21: 45986 | N21: 37 | O21: =VLOOKUP(N21,$A$15:$B$19,2,TRUE) -> 31-60 | P21: =IF(N21<=recency_threshold,"High","Low") -> High
D22: Customer-012 | E22: 45741 | F22: =IF(D22=D23,E23,"") -> 45896 | G22: =IF(F22="","",F22-E22) -> 155 | H22: =IF(G22="","",IF(G22<=return_window,1,0)) -> 0 | K22: Customer-021 | L22: =IF(SUMIFS($H$6:$H$2006,$D$6:$D$2006,K22),1,0) -> 0 | M22: 46015 | N22: 8 | O22: =VLOOKUP(N22,$A$15:$B$19,2,TRUE) -> 0-30 | P22: =IF(N22<=recency_threshold,"High","Low") -> High
D23: Customer-012 | E23: 45896 | F23: =IF(D23=D24,E24,"") -> 45950 | G23: =IF(F23="","",F23-E23) -> 54 | H23: =IF(G23="","",IF(G23<=return_window,1,0)) -> 0 | K23: Customer-023 | L23: =IF(SUMIFS($H$6:$H$2006,$D$6:$D$2006,K23),1,0) -> 1 | M23: 45937 | N23: 86 | O23: =VLOOKUP(N23,$A$15:$B$19,2,TRUE) -> 61-90 | P23: =IF(N23<=recency_threshold,"High","Low") -> Low
D24: Customer-012 | E24: 45950 | F24: =IF(D24=D25,E25,"") | G24: =IF(F24="","",F24-E24) | H24: =IF(G24="","",IF(G24<=return_window,1,0)) | K24: Customer-024 | L24: =IF(SUMIFS($H$6:$H$2006,$D$6:$D$2006,K24),1,0) -> 0 | M24: 45943 | N24: 80 | O24: =VLOOKUP(N24,$A$15:$B$19,2,TRUE) -> 61-90 | P24: =IF(N24<=recency_threshold,"High","Low") -> Low
D25: Customer-013 | E25: 45693 | F25: =IF(D25=D26,E26,"") -> 45744 | G25: =IF(F25="","",F25-E25) -> 51 | H25: =IF(G25="","",IF(G25<=return_window,1,0)) -> 0 | K25: Customer-025 | L25: =IF(SUMIFS($H$6:$H$2006,$D$6:$D$2006,K25),1,0) -> 0 | M25: 45673 | N25: 350 | O25: =VLOOKUP(N25,$A$15:$B$19,2,TRUE) -> 90+ | P25: =IF(N25<=recency_threshold,"High","Low") -> Low
D26: Customer-013 | E26: 45744 | F26: =IF(D26=D27,E27,"") -> 45978 | G26: =IF(F26="","",F26-E26) -> 234 | H26: =IF(G26="","",IF(G26<=return_window,1,0)) -> 0 | K26: Customer-026 | L26: =IF(SUMIFS($H$6:$H$2006,$D$6:$D$2006,K26),1,0) -> 1 | M26: 46021 | N26: 2 | O26: =VLOOKUP(N26,$A$15:$B$19,2,TRUE) -> 0-30 | P26: =IF(N26<=recency_threshold,"High","Low") -> High
D27: Customer-013 | E27: 45978 | F27: =IF(D27=D28,E28,"") | G27: =IF(F27="","",F27-E27) | H27: =IF(G27="","",IF(G27<=return_window,1,0)) | K27: Customer-027 | L27: =IF(SUMIFS($H$6:$H$2006,$D$6:$D$2006,K27),1,0) -> 0 | M27: 45744 | N27: 279 | O27: =VLOOKUP(N27,$A$15:$B$19,2,TRUE) -> 90+ | P27: =IF(N27<=recency_threshold,"High","Low") -> Low
D28: Customer-014 | E28: 45924 | F28: =IF(D28=D29,E29,"") | G28: =IF(F28="","",F28-E28) | H28: =IF(G28="","",IF(G28<=return_window,1,0)) | K28: Customer-028 | L28: =IF(SUMIFS($H$6:$H$2006,$D$6:$D$2006,K28),1,0) -> 0 | M28: 45733 | N28: 290 | O28: =VLOOKUP(N28,$A$15:$B$19,2,TRUE) -> 90+ | P28: =IF(N28<=recency_threshold,"High","Low") -> Low
D29: Customer-015 | E29: 45854 | F29: =IF(D29=D30,E30,"") | G29: =IF(F29="","",F29-E29) | H29: =IF(G29="","",IF(G29<=return_window,1,0)) | K29: Customer-029 | L29: =IF(SUMIFS($H$6:$H$2006,$D$6:$D$2006,K29),1,0) -> 0 | M29: 45954 | N29: 69 | O29: =VLOOKUP(N29,$A$15:$B$19,2,TRUE) -> 61-90 | P29: =IF(N29<=recency_threshold,"High","Low") -> Low
D30: Customer-016 | E30: 45727 | F30: =IF(D30=D31,E31,"") -> 45770 | G30: =IF(F30="","",F30-E30) -> 43 | H30: =IF(G30="","",IF(G30<=return_window,1,0)) -> 0 | K30: Customer-031 | L30: =IF(SUMIFS($H$6:$H$2006,$D$6:$D$2006,K30),1,0) -> 1 | M30: 45896 | N30: 127 | O30: =VLOOKUP(N30,$A$15:$B$19,2,TRUE) -> 90+ | P30: =IF(N30<=recency_threshold,"High","Low") -> Low
D31: Customer-016 | E31: 45770 | F31: =IF(D31=D32,E32,"") -> 45904 | G31: =IF(F31="","",F31-E31) -> 134 | H31: =IF(G31="","",IF(G31<=return_window,1,0)) -> 0 | K31: Customer-032 | L31: =IF(SUMIFS($H$6:$H$2006,$D$6:$D$2006,K31),1,0) -> 0 | M31: 45961 | N31: 62 | O31: =VLOOKUP(N31,$A$15:$B$19,2,TRUE) -> 61-90 | P31: =IF(N31<=recency_threshold,"High","Low") -> Low
... D818: Customer-429 | E818: 45911 | F818: =IF(D818=D819,E819,"") | G818: =IF(F818="","",F818-E818) | H818: =IF(G818="","",IF(G818<=return_window,1,0)) | K818: Customer-999 | L818: =IF(SUMIFS($H$6:$H$2006,$D$6:$D$2006,K818),1,0) -> 0 | M818: 45855 | N818: 168 | O818: =VLOOKUP(N818,$A$15:$B$19,2,TRUE) -> 90+ | P818: =IF(N818<=recency_threshold,"High","Low") -> Low
D819: Customer-430 | E819: 45674 | F819: =IF(D819=D820,E820,"") -> 45979 | G819: =IF(F819="","",F819-E819) -> 305 | H819: =IF(G819="","",IF(G819<=return_window,1,0)) -> 0
D820: Customer-430 | E820: 45979 | F820: =IF(D820=D821,E821,"") | G820: =IF(F820="","",F820-E820) | H820: =IF(G820="","",IF(G820<=return_window,1,0))
D821: Customer-431 | E821: 45790 | F821: =IF(D821=D822,E822,"") -> 45925 | G821: =IF(F821="","",F821-E821) -> 135 | H821: =IF(G821="","",IF(G821<=return_window,1,0)) -> 0
D822: Customer-431 | E822: 45925 | F822: =IF(D822=D823,E823,"") | G822: =IF(F822="","",F822-E822) | H822: =IF(G822="","",IF(G822<=return_window,1,0))
D823: Customer-432 | E823: 45979 | F823: =IF(D823=D824,E824,"") | G823: =IF(F823="","",F823-E823) | H823: =IF(G823="","",IF(G823<=return_window,1,0))
D824: Customer-433 | E824: 45748 | F824: =IF(D824=D825,E825,"") | G824: =IF(F824="","",F824-E824) | H824: =IF(G824="","",IF(G824<=return_window,1,0))
D825: Customer-437 | E825: 45910 | F825: =IF(D825=D826,E826,"") | G825: =IF(F825="","",F825-E825) | H825: =IF(G825="","",IF(G825<=return_window,1,0))
D826: Customer-438 | E826: 45778 | F826: =IF(D826=D827,E827,"") -> 45789 | G826: =IF(F826="","",F826-E826) -> 11 | H826: =IF(G826="","",IF(G826<=return_window,1,0)) -> 1
...

Sheet frequency
A1: User CMA Smart & Secure : Applied Data Analytics Training Center.
A2: http://www.facebook.com/cma.01012020
A3: Email: info@usercma.com Phone: 09 44717 2115
G4: Frequency = number of purchases per customer
G5: Transaction Count (from WK01)
A6: Frequency Threshold | C6: Customer ID | F6: Customer ID | G6: Frequency | H6: F Score | K6: Frequency | L6: ≥ Frequency | M6: Repeat Rate | N6: % Gap | O6: Change of Change | Q6: Second derivative (Curvature)
A7: 3 | C7: Customer-002 | F7: Customer-002 | G7: 3 | H7: =IF(G7>=frequency_threshold,"High","Low") -> High | K7: 1 | L7: =COUNTIFS($G$7:$G$818,">="&K7) -> 812 | M7: =L7/$L$7 -> 1
C8: Customer-002 | F8: Customer-004 | G8: 5 | H8: =IF(G8>=frequency_threshold,"High","Low") -> High | K8: 2 | L8: =COUNTIFS($G$7:$G$818,">="&K8) -> 520 | M8: =L8/$L$7 -> 0.64039409 | N8: =M7-M8 -> 0.35960591
C9: Customer-002 | F9: Customer-005 | G9: 2 | H9: =IF(G9>=frequency_threshold,"High","Low") -> Low | K9: 3 | L9: =COUNTIFS($G$7:$G$818,">="&K9) -> 313 | M9: =L9/$L$7 -> 0.38546798 | N9: =M8-M9 -> 0.25492611 | O9: =N8-N9 -> 0.1046798
C10: Customer-004 | F10: Customer-006 | G10: 1 | H10: =IF(G10>=frequency_threshold,"High","Low") -> Low | K10: 4 | L10: =COUNTIFS($G$7:$G$818,">="&K10) -> 163 | M10: =L10/$L$7 -> 0.20073892 | N10: =M9-M10 -> 0.18472906 | O10: =N9-N10 -> 0.070197044
C11: Customer-004 | F11: Customer-007 | G11: 1 | H11: =IF(G11>=frequency_threshold,"High","Low") -> Low | K11: 5 | L11: =COUNTIFS($G$7:$G$818,">="&K11) -> 85 | M11: =L11/$L$7 -> 0.1046798 | N11: =M10-M11 -> 0.096059113 | O11: =N10-N11 -> 0.088669951
C12: Customer-004 | F12: Customer-008 | G12: 1 | H12: =IF(G12>=frequency_threshold,"High","Low") -> Low | K12: 6 | L12: =COUNTIFS($G$7:$G$818,">="&K12) -> 56 | M12: =L12/$L$7 -> 0.068965517 | N12: =M11-M12 -> 0.035714286 | O12: =N11-N12 -> 0.060344828
C13: Customer-004 | F13: Customer-009 | G13: 2 | H13: =IF(G13>=frequency_threshold,"High","Low") -> Low | K13: 7 | L13: =COUNTIFS($G$7:$G$818,">="&K13) -> 30 | M13: =L13/$L$7 -> 0.036945813 | N13: =M12-M13 -> 0.032019704 | O13: =N12-N13 -> 0.0036945813
C14: Customer-004 | F14: Customer-012 | G14: 3 | H14: =IF(G14>=frequency_threshold,"High","Low") -> High | K14: 8 | L14: =COUNTIFS($G$7:$G$818,">="&K14) -> 12 | M14: =L14/$L$7 -> 0.014778325 | N14: =M13-M14 -> 0.022167488 | O14: =N13-N14 -> 0.0098522167
C15: Customer-005 | F15: Customer-013 | G15: 3 | H15: =IF(G15>=frequency_threshold,"High","Low") -> High | K15: 9 | L15: =COUNTIFS($G$7:$G$818,">="&K15) -> 7 | M15: =L15/$L$7 -> 0.0086206897 | N15: =M14-M15 -> 0.0061576355 | O15: =N14-N15 -> 0.016009852
C16: Customer-005 | F16: Customer-014 | G16: 1 | H16: =IF(G16>=frequency_threshold,"High","Low") -> Low | K16: 10 | L16: =COUNTIFS($G$7:$G$818,">="&K16) -> 2 | M16: =L16/$L$7 -> 0.0024630542 | N16: =M15-M16 -> 0.0061576355 | O16: =N15-N16 -> 0
C17: Customer-006 | F17: Customer-015 | G17: 1 | H17: =IF(G17>=frequency_threshold,"High","Low") -> Low
C18: Customer-007 | F18: Customer-016 | G18: 3 | H18: =IF(G18>=frequency_threshold,"High","Low") -> High | L18: =COUNTIFS($G$7:$G$818,">="&K7)
C19: Customer-008 | F19: Customer-017 | G19: 3 | H19: =IF(G19>=frequency_threshold,"High","Low") -> High | L19: =M7-M8
C20: Customer-009 | F20: Customer-019 | G20: 3 | H20: =IF(G20>=frequency_threshold,"High","Low") -> High | L20: =N8-N9
C21: Customer-009 | F21: Customer-020 | G21: 5 | H21: =IF(G21>=frequency_threshold,"High","Low") -> High
C22: Customer-012 | F22: Customer-021 | G22: 2 | H22: =IF(G22>=frequency_threshold,"High","Low") -> Low
C23: Customer-012 | F23: Customer-023 | G23: 3 | H23: =IF(G23>=frequency_threshold,"High","Low") -> High
C24: Customer-012 | F24: Customer-024 | G24: 2 | H24: =IF(G24>=frequency_threshold,"High","Low") -> Low
C25: Customer-013 | F25: Customer-025 | G25: 1 | H25: =IF(G25>=frequency_threshold,"High","Low") -> Low
C26: Customer-013 | F26: Customer-026 | G26: 3 | H26: =IF(G26>=frequency_threshold,"High","Low") -> High
C27: Customer-013 | F27: Customer-027 | G27: 1 | H27: =IF(G27>=frequency_threshold,"High","Low") -> Low
C28: Customer-014 | F28: Customer-028 | G28: 2 | H28: =IF(G28>=frequency_threshold,"High","Low") -> Low
C29: Customer-015 | F29: Customer-029 | G29: 1 | H29: =IF(G29>=frequency_threshold,"High","Low") -> Low
C30: Customer-016 | F30: Customer-031 | G30: 2 | H30: =IF(G30>=frequency_threshold,"High","Low") -> Low
C31: Customer-016 | F31: Customer-032 | G31: 4 | H31: =IF(G31>=frequency_threshold,"High","Low") -> High
C32: Customer-016 | F32: Customer-033 | G32: 2 | H32: =IF(G32>=frequency_threshold,"High","Low") -> Low
... C818: Customer-429 | F818: Customer-999 | G818: 2 | H818: =IF(G818>=frequency_threshold,"High","Low") -> Low
C819: Customer-430
C820: Customer-430
C821: Customer-431
C822: Customer-431
C823: Customer-432
C824: Customer-433
C825: Customer-437
...

Sheet monetary
A1: User CMA Smart & Secure : Applied Data Analytics Training Center.
A2: http://www.facebook.com/cma.01012020
A3: Email: info@usercma.com Phone: 09 44717 2115
B5: Customer ID | C5: Amount | D5: % on Total | E5: Cumulative % | F5: M Score (H/L) | M5: Score
B6: Customer-732 | C6: 1516250000 | D6: =C6/SUM($C$6:$C$817) -> 0.025333492 | E6: =D6 -> 0.025333492 | F6: High | I6: 80 | J6: 20 | L6: Values | M6: High | N6: Low
B7: Customer-620 | C7: 1357000000 | D7: =C7/SUM($C$6:$C$817) -> 0.022672744 | E7: =E6+D7 -> 0.048006235 | F7: High | I7: land | J7: population | L7: Customer ID | M7: 0.1637931 | N7: 0.8362069
B8: Customer-193 | C8: 1332050000 | D8: =C8/SUM($C$6:$C$817) -> 0.02225588 | E8: =E7+D8 -> 0.070262115 | F8: High | L8: Amount | M8: 0.79947629 | N8: 0.20052371
B9: Customer-499 | C9: 1265250000 | D9: =C9/SUM($C$6:$C$817) -> 0.021139786 | E9: =E8+D9 -> 0.091401901 | F9: High
B10: Customer-251 | C10: 1214250000 | D10: =C10/SUM($C$6:$C$817) -> 0.020287678 | E10: =E9+D10 -> 0.11168958 | F10: High | I10: 80 | J10: 20
B11: Customer-282 | C11: 1186900000 | D11: =C11/SUM($C$6:$C$817) -> 0.019830715 | E11: =E10+D11 -> 0.13152029 | F11: High | I11: revenue | J11: customers
B12: Customer-044 | C12: 1165500000 | D12: =C12/SUM($C$6:$C$817) -> 0.019473164 | E12: =E11+D12 -> 0.15099346 | F12: High
B13: Customer-977 | C13: 1161100000 | D13: =C13/SUM($C$6:$C$817) -> 0.019399648 | E13: =E12+D13 -> 0.17039311 | F13: High
B14: Customer-241 | C14: 1151500000 | D14: =C14/SUM($C$6:$C$817) -> 0.019239252 | E14: =E13+D14 -> 0.18963236 | F14: High
B15: Customer-410 | C15: 1138500000 | D15: =C15/SUM($C$6:$C$817) -> 0.019022048 | E15: =E14+D15 -> 0.20865441 | F15: High
B16: Customer-495 | C16: 1137600000 | D16: =C16/SUM($C$6:$C$817) -> 0.019007011 | E16: =E15+D16 -> 0.22766142 | F16: High
B17: Customer-246 | C17: 1135000000 | D17: =C17/SUM($C$6:$C$817) -> 0.01896357 | E17: =E16+D17 -> 0.24662499 | F17: High
B18: Customer-985 | C18: 1105000000 | D18: =C18/SUM($C$6:$C$817) -> 0.01846233 | E18: =E17+D18 -> 0.26508732 | F18: High
B19: Customer-816 | C19: 1093500000 | D19: =C19/SUM($C$6:$C$817) -> 0.018270188 | E19: =E18+D19 -> 0.2833575 | F19: High
B20: Customer-180 | C20: 1079600000 | D20: =C20/SUM($C$6:$C$817) -> 0.018037947 | E20: =E19+D20 -> 0.30139545 | F20: High
B21: Customer-806 | C21: 1045300000 | D21: =C21/SUM($C$6:$C$817) -> 0.017464863 | E21: =E20+D21 -> 0.31886031 | F21: High
B22: Customer-872 | C22: 1033750000 | D22: =C22/SUM($C$6:$C$817) -> 0.017271886 | E22: =E21+D22 -> 0.3361322 | F22: High
B23: Customer-074 | C23: 1027500000 | D23: =C23/SUM($C$6:$C$817) -> 0.017167461 | E23: =E22+D23 -> 0.35329966 | F23: High
... B817: Customer-007 | C817: 250000 | D817: =C817/SUM($C$6:$C$817) -> 4.1769978e-06 | E817: =E816+D817 -> 1 | F817: Low

Sheet WK02
A1: User CMA Smart & Secure : Applied Data Analytics Training Center.
A2: http://www.facebook.com/cma.01012020
A3: Email: info@usercma.com Phone: 09 44717 2115
B5: RFM Distribution | G5: Segment Revenue Contribution | L5: Customer Count by Segment
B6: (Show distribution of Recency, Frequency, Monetary scores) | G6: (Show which segment generates most revenue) | L6: (How many customers in each group)
B8: Recency Distribution (H - Active, L - Inactive) | G8: Segments | H8: Total Amount | I8: % on Total | L8: Segments | M8: Count of Customer ID | N8: % on Total
G9: 🛒 Big Spenders (Occasional) | H9: 388800000 | I9: 0.0064960669 | L9: ⚠️ At Risk High Value | M9: 47 | N9: 0.057881773
B10: Row Labels | C10: Count of Customer ID | D10: % on Total | G10: 💸 Lost High Spenders | H10: 733000000 | I10: 0.012246957 | L10: 🌱 Potential Loyalists | M10: 108 | N10: 0.13300493
B11: High | C11: 280 | D11: 0.34482759 | G11: 🌱 Potential Loyalists | H11: 1715470000 | I11: 0.028662057 | L11: 💎 Loyal High Value | M11: 99 | N11: 0.12192118
B12: Low | C12: 532 | D12: 0.65517241 | G12: 💎 Loyal High Value | H12: 2565690000 | I12: 0.042867526 | L12: 💤 Lost / Low Value | M12: 371 | N12: 0.45689655
B13: Grand Total | C13: 812 | D13: 1 | G13: 🔁 Former Loyal Low Spend | H13: 2765895000 | I13: 0.046212549 | L13: 💸 Lost High Spenders | M13: 13 | N13: 0.016009852
G14: 💤 Lost / Low Value | H14: 4954610000 | I14: 0.08278158 | L14: 🔁 Former Loyal Low Spend | M14: 101 | N14: 0.12438424
G15: ⚠️ At Risk High Value | H15: 14921080000 | I15: 0.24930127 | L15: 🛒 Big Spenders (Occasional) | M15: 7 | N15: 0.0086206897
B16: Frequency Distribution (H - Loyal, L - Ocassional) | G16: 🥇 Champions | H16: 31807055000 | I16: 0.53143199 | L16: 🥇 Champions | M16: 66 | N16: 0.081280788
G17: Grand Total | H17: 59851600000 | I17: 1 | L17: Grand Total | M17: 812 | N17: 1
B18: Row Labels | C18: Count of Customer ID | D18: % on Total
B19: High | C19: 313 | D19: 0.38546798
B20: Low | C20: 499 | D20: 0.61453202
B21: Grand Total | C21: 812 | D21: 1 | L21: Row Labels | M21: Count of Customer ID | N21: % of Customer | O21: Sum of Total Amount | P21: % of Total
L22: 🔁 Former Loyal Low Spend | M22: 19 | N22: 0.023399015 | O22: 254625000 | P22: 0.0042542722
L23: 💎 Loyal High Value | M23: 36 | N23: 0.044334975 | O23: 442545000 | P23: 0.0073940379
B24: Monetary Score (H - Valuable, L - Low value) | L24: 🌱 Potential Loyalists | M24: 122 | N24: 0.15024631 | O24: 1064015000 | P24: 0.017777553
L25: 💤 Lost / Low Value | M25: 229 | N25: 0.2820197 | O25: 1789420000 | P25: 0.029897613
B26: Row Labels | C26: Count of Customer ID | D26: % on Total | L26: 🛒 Big Spenders (Occasional) | M26: 62 | N26: 0.07635468 | O26: 2114200000 | P26: 0.035324035
B27: Low | C27: 679 | D27: 0.8362069 | L27: 💸 Lost High Spenders | M27: 86 | N27: 0.10591133 | O27: 2824245000 | P27: 0.04718746
B28: High | C28: 133 | D28: 0.1637931 | L28: ⚠️ At Risk High Value | M28: 75 | N28: 0.092364532 | O28: 9302985000 | P28: 0.15543419
B29: Grand Total | C29: 812 | D29: 1 | L29: 🥇 Champions | M29: 183 | N29: 0.22536946 | O29: 42059565000 | P29: 0.70273084
L30: Grand Total | M30: 812 | N30: 1 | O30: 59851600000 | P30: 1

Sheet WK03
A1: User CMA Smart & Secure : Applied Data Analytics Training Center.
A2: http://www.facebook.com/cma.01012020
A3: Email: info@usercma.com Phone: 09 44717 2115
B6: RFM Customer Segmentation Dashboard
B8: (1) Executive Summary
B9: (1.1) KPI Cards (4–5 only)
B10: Total Customers
B11: Total Revenue
B12: % Active Customers (R High)
B13: % Loyal Customers (F High)
B14: % High Value Customers (M High)
B15: (1.2) Key Insight Text Box
B17: (2) Diagnostic Analysis
B18: (2.1) RFM Distribution (100% Stacked Bar, 3 bars only)
B19: (2.2) Segment Revenue vs Customer Count (Bubble Chart or Scatter Plot)
... B30: (3.3) Filter (Region) (⚠️ keep minimal)

Sheet Next
A1: User CMA Smart & Secure : Applied Data Analytics Training Center.
A2: http://www.facebook.com/cma.01012020
A3: Email: info@usercma.com Phone: 09 44717 2115
B5: ⏭️ Next Actions
B8: 1. Move Beyond Excel → Advanced Tools
B10: We have successfully learned RFM using Excel. However, for real-world applications, Excel has limitations.
B11: 👉 Let’s start exploring tools like Python, KNIME, Power BI, etc.
B13: 📌 Why this is important:
B14: (1.1) Model Exploration (Return Window Testing)
B15: RFM analysis requires testing multiple return windows (15, 30, 45, 60 days)
B16: Excel = manual, time-consuming
B17: Advanced tools = faster, scalable, repeatable testing
B19: (1.2) Automation for Periodic Analysis
B20: RFM is NOT one-time → must run monthly / periodically
B21: Excel = manual refresh every time
... B62: Move from painting → analytics

Sheet Sheet1
A1: User CMA Smart & Secure : Applied Data Analytics Training Center.
A2: http://www.facebook.com/cma.01012020
A3: Email: info@usercma.com Phone: 09 44717 2115
